<?xml version="1.0"?>

<robot xmlns:xacro="http://www.ros.org/wiki/xacro">

  <xacro:property name="pi" value="3.1415926535897931" />
  <xacro:property name="M_PI" value="3.1415926535897931" />

<!--   <xacro:include filename="$(find hku_m100_description)/urdf/hku_m100.gazebo" />
 -->  
 <!-- Main quadrotor link -->
  <xacro:macro name="hku_m100_base_macro">
    <link name="drone"> <!-- base_link -->
      <inertial>
        <mass value="2.477" />
        <origin xyz="0 0 0" />
        <inertia ixx="0.01152" ixy="0.0" ixz="0.0" iyy="0.01152" iyz="0.0" izz="0.0218" />
      </inertial>

    </link>


<!-- ###################################################################################################### -->
<!-- ###################################################################################################### -->

<!-- HOKUYO -->

<!-- ###################################################################################################### -->
<!-- ###################################################################################################### -->

    <joint name="laser_joint" type="fixed">
      <!-- <origin xyz="0 0 0" rpy="0 0 0" /> -->
      <origin xyz="0.1 0 0.125" rpy="0 0 0" /> 
      <parent link="drone" />
      <child link="hokuyo_link" />
    </joint>

    <link name="hokuyo_link"> 
      <visual> 
        <!-- <origin xyz="0 0 -0.03" rpy="0 0 0"/> -->
        <origin xyz="0 0 0" rpy="0 0 0"/>
        <geometry> 
          <box size="0.065 0.065 0.07"/> 
        </geometry>
        <material name="Green"/> 
      </visual>
      <inertial>
        <mass value="0.001"/>
        <origin xyz="0 0 0"/>
        <inertia ixx="0.0001" ixy="0.0" ixz="0.0" iyy="0.0001" iyz="0.0" izz="0.0001"/>
      </inertial>
    </link>

  <gazebo reference="hokuyo_link">
    <sensor type="gpu_ray" name="head_hokuyo_sensor">
      <pose>0 0 0 0 0 0</pose>
      <visualize>true</visualize>
      <update_rate>40</update_rate>
      <ray>
        <scan>
          <horizontal>
            <samples>1081</samples>
            <!-- <resolution>0.25</resolution> -->
            <min_angle>-2.35619449615</min_angle>
            <max_angle>2.35619449615</max_angle>
          </horizontal>
        </scan>
        <range>
          <min>0.10</min>
          <max>10.0</max>
          <resolution>0.01</resolution>
        </range>
        <noise>
          <type>gaussian</type>
          <!-- Noise parameters based on published spec for Hokuyo laser
               achieving "+-30mm" accuracy at range < 10m.  A mean of 0.0m and
               stddev of 0.01m will put 99.7% of samples within 0.03m of the true
               reading. -->
          <mean>0.0</mean>
          <stddev>0.001</stddev>
        </noise>
      </ray>
      <plugin name="gazebo_ros_head_hokuyo_controller" filename="libgazebo_ros_gpu_laser.so">
        <topicName>/dtu_controller/scan</topicName>
        <frameName>hokuyo_link</frameName>
      </plugin>
    </sensor>
  </gazebo>

<!-- ###################################################################################################### -->
<!-- ###################################################################################################### -->

<!-- CAMERA -->

<!-- ###################################################################################################### -->
<!-- ###################################################################################################### -->

    <joint name="camera_joint" type="floating">
      <origin xyz="0.1 0 -0.04" rpy="0 0 0"/>
      <parent link="drone"/>
      <child link="camera_link"/>
    </joint>
    
    <link name="camera_link">
      <inertial>
        <mass value="0.0010" />
        <origin xyz="0 0 0" rpy="0 0 0" />
        <inertia ixx="0.0001" ixy="0" ixz="0" iyy="0.0001" iyz="0" izz="0.0001" />
      </inertial>
      <visual>
        <origin xyz="0 0 0" rpy="0 0 0" />
        <geometry>
          <mesh filename="package://hku_m100_description/meshes/hku_m100/gimbal.dae"/>
        </geometry>
      </visual>
      <collision>
        <origin xyz="0 0 0" rpy="0 0 0" />
        <geometry>
          <mesh filename="package://hku_m100_description/meshes/hku_m100/gimbal.stl"/>
        </geometry>
      </collision>
    </link>
    
    <!-- <joint name="camera_optical_joint" type="floating">
      <origin xyz="0 0 0" rpy="${-M_PI/2} 0.0 ${-M_PI/2}" />
      <parent link="camera_link" />
      <child link="camera_optical_frame"/>
    </joint>
  
    <link name="camera_optical_frame"/> -->
    
    <gazebo reference="camera_link">
      <sensor type="camera" name="camera_camera_sensor">
        <update_rate>30</update_rate>
        <camera>
          <!-- <pose>0.027 0 -0.027 0 1.57 0</pose> -->
          <!-- <pose>0.027 0 -0.027 0 1.57 0</pose> -->
          <pose>0.027 0 -0.027 0 0 0</pose>
          <horizontal_fov>${61 * M_PI/180.0}</horizontal_fov>
          <!-- <vertical_fov>${46.6 * M_PI/180.0}</vertical_fov> -->
          <image>
            <format>R8G8B8</format>
            <width>1280</width>
            <height>720</height>
          </image>
          <clip>
            <near>0.01</near>
            <far>100</far>
          </clip>
        </camera>

        <plugin name="camera_controller" filename="libgazebo_ros_camera.so">
          <cameraName>camera</cameraName>
          <alwaysOn>true</alwaysOn>
          <updateRate>30</updateRate>
          <!-- <focal_length>1070</focal_length> -->
          <imageTopicName>/usb_cam/image_raw</imageTopicName>
          <cameraInfoTopicName>/usb_cam/camera_info</cameraInfoTopicName>
          <!-- <imageTopicName>camera/image</imageTopicName> -->
          <!-- <cameraInfoTopicName>camera/camera_info</cameraInfoTopicName> -->
          <frameName>camera_optical_frame</frameName>
        </plugin>
      </sensor>

    </gazebo>

  </xacro:macro>
</robot>

